## 1. **Try/Catch**

A estrutura `try/catch` é usada para tentar executar um bloco de código e capturar qualquer erro que ocorra durante a execução. Caso um erro seja lançado dentro do bloco `try`, o controle passa para o bloco `catch`.

### Exemplo:

```typescript
function divide(a: number, b: number): number {
  try {
    if (b === 0) {
      throw new Error("Divisão por zero não permitida!");
    }
    return a / b;
  } catch (error) {
    console.error("Erro:", error.message);
    return 0; // Valor padrão em caso de erro
  }
}

console.log(divide(10, 0)); // Vai exibir erro "Divisão por zero não permitida!"
```


## 2. **Promises com `.catch()`**

Quando lidamos com operações assíncronas, podemos utilizar `Promises` e capturar erros com o método `.catch()`. Esse método é chamado caso a Promise seja rejeitada.

### Exemplo:

```typescript
function fetchData(): Promise<string> {
  return new Promise((resolve, reject) => {
    const success = Math.random() > 0.5;
    if (success) {
      resolve("Dados carregados com sucesso");
    } else {
      reject(new Error("Falha ao carregar dados"));
    }
  });
}

fetchData()
  .then((message) => console.log(message))
  .catch((error) => console.error("Erro:", error.message));
```


## 3. **Assertivas e Validações com `throw`**

Em algumas situações, podemos lançar manualmente erros com a palavra-chave `throw`. Isso é útil quando precisamos garantir que condições específicas sejam atendidas antes de prosseguir com a execução do código.

### Exemplo:

```typescript
function validateAge(age: number): void {
  if (age < 18) {
    throw new Error("A idade precisa ser 18 ou mais.");
  }
  console.log("Idade válida");
}

try {
  validateAge(16); // Vai lançar erro
} catch (error) {
  console.error("Erro:", error.message);
}
