## 1. Limitações do `try/catch`

A estrutura `try/catch` é utilizada para capturar erros em código síncrono, mas ela possui algumas limitações.

### Limitação:

- **Execução síncrona**: O `try/catch` funciona apenas para capturar erros em operações **síncronas**. Ele não captura erros que ocorrem em operações assíncronas, como `setTimeout`, `Promises` ou `async/await`.

### Exemplo de Limitação:

```typescript
try {
  setTimeout(() => {
    throw new Error("Erro assíncrono");
  }, 1000);
} catch (error) {
  console.error("Isso não irá capturar o erro!");
}
```


## 2. Limitações das Promises com `.catch()`


### Limitação:

- **Erros fora do fluxo da Promise**: O `.catch()` só captura erros dentro do fluxo da Promise. Caso um erro ocorra fora da Promise, ele não será capturado pelo `.catch()`.

### Exemplo de Limitação:

```typescript
function fetchData(): Promise<string> {
  return new Promise((resolve, reject) => {
    const success = Math.random() > 0.5;
    if (success) {
      resolve("Dados carregados com sucesso");
    } else {
      reject(new Error("Falha ao carregar dados"));
    }
  });
}

fetchData()
  .then((message) => console.log(message))
  .catch((error) => console.error("Erro:", error.message));

// Se houver um erro fora da Promise, ele não será capturado pelo `.catch()`:
console.log(nonExistentFunction()); // Isso não será capturado pelo `.catch()`
```

## 3. Limitações do `throw`
### Limitação:

- **Controle manual de erros**: O `throw` exige que o desenvolvedor faça o controle manual dos erros, ou seja, deve decidir onde lançar erros e garantir que as condições corretas sejam verificadas. Isso pode levar a **erro humano** se não for bem controlado, como lançar erros desnecessários ou não lançar erros quando deveria.

### Exemplo de Limitação:

```typescript
function divide(a: number, b: number): number {
  if (b === 0) {
    throw new Error("Divisão por zero não permitida!");
  }
  return a / b;
}

try {
  // Erro lançado explicitamente
  divide(10, 0);
} catch (error) {
  console.error("Erro:", error.message);
}

// Mas se esquecermos de lançar o erro quando b for zero, o problema persiste.
```